Workbook
Name _: #REF!
Name ___yr20: #REF!
Name ___yr88: #REF!
Name __1_: #REF!
Name __UP1: #REF!
Name __UP10: #REF!
Name __UP11: #REF!
Name __UP12: #REF!
Name __UP13: #REF!
Name __UP14: #REF!
Name __UP15: #REF!
Name __UP16: #REF!
Name __UP17: #REF!
Name __UP18: #REF!
Name __UP19: #REF!
Name __UP2: #REF!
Name __UP20: #REF!
Name __UP21: #REF!
Name __UP22: #REF!
Name __UP3: #REF!
Name __UP4: #REF!
Name __UP5: #REF!
Name __UP6: #REF!
Name __UP7: #REF!
Name __UP8: #REF!
Name __UP9: #REF!
Name _1_: #REF!
Name _2015_IHS: #REF!
Name _2016_IHS: '[1]us domestic'!#REF!
Name _2016_South_American_construction_spending_by_country: #REF!
Name _2016_South_American_construction_spending_by_sector: '[1]SA Constuction Spend by Sector'!#REF!
Name _2017_IHS: #REF!
Name _2018_IHS: #REF!
Name _2021_IHS: #REF!
Name _UP1: #REF!
Name _UP10: #REF!
Name _UP11: #REF!
Name _UP12: #REF!
Name _UP13: #REF!
Name _UP14: #REF!
Name _UP15: #REF!
Name _UP16: #REF!
Name _UP17: #REF!
Name _UP18: #REF!
Name _UP19: #REF!
Name _UP2: #REF!
Name _UP20: #REF!
Name _UP21: #REF!
Name _UP22: #REF!
Name _UP3: #REF!
Name _UP4: #REF!
Name _UP5: #REF!
Name _UP6: #REF!
Name _UP7: #REF!
Name _UP8: #REF!
Name _UP9: #REF!
Name _yr01: #REF!
Name _yr02: #REF!
Name _yr03: #REF!
Name _yr04: #REF!

Sheet Sheet8
A3: 행 레이블 | B3: 평균 : Compound annual growth rate. 2025-30(percent)
A4: Cleaners, industrial and institutional | B4: 0.031225525
A5: Coatings, high-performance anticorrosion | B5: 0.012810807
A6: Coatings, radiation curable | B6: 0.036406497
A7: Coatings, thermosetting powder | B7: 0.032355537
A8: Compounded engineering thermoplastics | B8: 0.031736002
A9: Construction chemicals | B9: 0.014720546
A10: Cosmetic/personal care chemicals | B10: 0.032234487
A11: Display materials | B11: 0.029390726
A12: Emission control | B12: -0.040973241
A13: Feed additives | B13: 0.024394642
A14: Flavors and fragrances | B14: 0.025565913
A15: Food additives | B15: 0.024455755
... A34: 총합계 | B34: 0.029831754

Sheet end_use_specialty
A1: end_use_id | B1: end_use_category | C1: specialty_category | D1: specialty_cagr | E1: Linkage 사유
A2: E01 | B2: Construction & Infrastructure | C2: Construction chemicals | D2: =_xlfn.XLOOKUP(표16[[#This Row],[specialty_category]],Sheet8!$A$4:$A$33,Sheet8!$B$4:$B$33) -> 0.014720546 | E2: 콘크리트 혼화제, 방수재, 보수재 등 건설용 기능성 화학소재
A3: E01 | B3: Construction & Infrastructure | C3: Coatings, high-performance anticorrosion | D3: =_xlfn.XLOOKUP(표16[[#This Row],[specialty_category]],Sheet8!$A$4:$A$33,Sheet8!$B$4:$B$33) -> 0.012810807 | E3: 철강, 콘크리트, 교량, 플랜트, 해양구조물 부식 방지
A4: E01 | B4: Construction & Infrastructure | C4: Coatings, thermosetting powder | D4: =_xlfn.XLOOKUP(표16[[#This Row],[specialty_category]],Sheet8!$A$4:$A$33,Sheet8!$B$4:$B$33) -> 0.032355537 | E4: 건축자재, 금속 구조물, 창호, 외장재 코팅
A5: E01 | B5: Construction & Infrastructure | C5: Specialty adhesives and sealants | D5: =_xlfn.XLOOKUP(표16[[#This Row],[specialty_category]],Sheet8!$A$4:$A$33,Sheet8!$B$4:$B$33) -> 0.026834875 | E5: 건축용 실란트, 접착제, 방수·기밀 소재
A6: E01 | B6: Construction & Infrastructure | C6: Water management chemicals | D6: =_xlfn.XLOOKUP(표16[[#This Row],[specialty_category]],Sheet8!$A$4:$A$33,Sheet8!$B$4:$B$33) -> 0.030939657 | E6: 상하수, 정수, 폐수처리 등 인프라 운영용 화학소재
A7: E01 | B7: Construction & Infrastructure | C7: Plastics additives | D7: =_xlfn.XLOOKUP(표16[[#This Row],[specialty_category]],Sheet8!$A$4:$A$33,Sheet8!$B$4:$B$33) -> 0.027418968 | E7: PVC pipe, insulation, flooring, 건축용 플라스틱 소재 성능 개선
A8: E01 | B8: Construction & Infrastructure | C8: High-performance thermoplastics | D8: =_xlfn.XLOOKUP(표16[[#This Row],[specialty_category]],Sheet8!$A$4:$A$33,Sheet8!$B$4:$B$33) -> 0.034040616 | E8: 고내열·고강도 건축 부품, 특수 배관, 절연재 등에 일부 적용
A9: E02 | B9: Consumer Products & Packaging | C9: Specialty films | D9: =_xlfn.XLOOKUP(표16[[#This Row],[specialty_category]],Sheet8!$A$4:$A$33,Sheet8!$B$4:$B$33) -> 0.029377151 | E9: 식품·생활용품 포장필름, 보호필름, 기능성 포장재
A10: E02 | B10: Consumer Products & Packaging | C10: Plastics additives | D10: =_xlfn.XLOOKUP(표16[[#This Row],[specialty_category]],Sheet8!$A$4:$A$33,Sheet8!$B$4:$B$33) -> 0.027418968 | E10: 포장재, 생활용 플라스틱 제품의 내구성·가공성·색상·안정성 개선
A11: E02 | B11: Consumer Products & Packaging | C11: Cosmetic/personal care chemicals | D11: =_xlfn.XLOOKUP(표16[[#This Row],[specialty_category]],Sheet8!$A$4:$A$33,Sheet8!$B$4:$B$33) -> 0.032234487 | E11: 화장품, 퍼스널케어 제품용 기능성 원료
A12: E02 | B12: Consumer Products & Packaging | C12: Printing inks | D12: =_xlfn.XLOOKUP(표16[[#This Row],[specialty_category]],Sheet8!$A$4:$A$33,Sheet8!$B$4:$B$33) -> 0.025897745 | E12: 포장재, 라벨, 상업 인쇄물용 잉크
A13: E02 | B13: Consumer Products & Packaging | C13: Flavors and fragrances | D13: =_xlfn.XLOOKUP(표16[[#This Row],[specialty_category]],Sheet8!$A$4:$A$33,Sheet8!$B$4:$B$33) -> 0.025565913 | E13: 식품, 생활용품, 화장품 향료·향미 소재
... A73: E08 | B73: Electronics, Semiconductors & Digital Infrastructure | C73: Coatings, radiation curable | D73: =_xlfn.XLOOKUP(표16[[#This Row],[specialty_category]],Sheet8!$A$4:$A$33,Sheet8!$B$4:$B$33) -> 0.036406497 | E73: 전자부품 보호코팅, 디스플레이·필름 코팅
B75: end_use_category | C75: specialty_counts | D75: speacialty_avg_cagr
B76: {=_xlfn.UNIQUE(표16[end_use_category])} -> Construction & Infrastructure | C76: =COUNTIF(표16[end_use_category],B76) -> 7 | D76: =AVERAGEIF(표16[end_use_category],B76,표16[specialty_cagr]) -> 0.025588715
B77: Consumer Products & Packaging | C77: =COUNTIF(표16[end_use_category],B77) -> 11 | D77: =AVERAGEIF(표16[end_use_category],B77,표16[specialty_cagr]) -> 0.027473582
B78: Automotive & Future Mobility | C78: =COUNTIF(표16[end_use_category],B78) -> 9 | D78: =AVERAGEIF(표16[end_use_category],B78,표16[specialty_cagr]) -> 0.01870127
B79: Energy, Power & Utilities | C79: =COUNTIF(표16[end_use_category],B79) -> 9 | D79: =AVERAGEIF(표16[end_use_category],B79,표16[specialty_cagr]) -> 0.01205622
B80: Healthcare & Life Sciences | C80: =COUNTIF(표16[end_use_category],B80) -> 6 | D80: =AVERAGEIF(표16[end_use_category],B80,표16[specialty_cagr]) -> 0.030983783
B81: Agriculture | C81: =COUNTIF(표16[end_use_category],B81) -> 5 | D81: =AVERAGEIF(표16[end_use_category],B81,표16[specialty_cagr]) -> 0.027317235
B82: Industrial Goods & Advanced Manufacturing | C82: =COUNTIF(표16[end_use_category],B82) -> 16 | D82: =AVERAGEIF(표16[end_use_category],B82,표16[specialty_cagr]) -> 0.023583045
B83: Electronics, Semiconductors & Digital Infrastructure | C83: =COUNTIF(표16[end_use_category],B83) -> 9 | D83: =AVERAGEIF(표16[end_use_category],B83,표16[specialty_cagr]) -> 0.038348693
B86: Specialty Category | C86: Description | D86: CAGR | E86: Construction & Infrastructure | F86: Consumer Products & Packaging | G86: Automotive & Future Mobility | H86: Energy, Power & Utilities | I86: Healthcare & Life Sciences | J86: Agriculture | K86: Industrial Goods & Advanced Manufacturing | L86: Electronics, Semiconductors & Digital Infrastructure
B87: Semiconductors, silicon and IC process chemicals | C87: 반도체(Chip) 제조 공정에 사용되는 초고순도 전자재료 및 공정용 화학 산업 | D87: =_xlfn.XLOOKUP(B87,Sheet8!$A$4:$A$33,Sheet8!$B$4:$B$33) -> 0.070838454 | E87: =IFERROR(AVERAGEIFS(표16[specialty_cagr],표16[specialty_category],$B87,표16[end_use_category],E$86),"") | F87: =IFERROR(AVERAGEIFS(표16[specialty_cagr],표16[specialty_category],$B87,표16[end_use_category],F$86),"") | G87: =IFERROR(AVERAGEIFS(표16[specialty_cagr],표16[specialty_category],$B87,표16[end_use_category],G$86),"") | H87: =IFERROR(AVERAGEIFS(표16[specialty_cagr],표16[specialty_category],$B87,표16[end_use_category],H$86),"") | I87: =IFERROR(AVERAGEIFS(표16[specialty_cagr],표16[specialty_category],$B87,표16[end_use_category],I$86),"") | J87: =IFERROR(AVERAGEIFS(표16[specialty_cagr],표16[specialty_category],$B87,표16[end_use_category],J$86),"") | K87: =IFERROR(AVERAGEIFS(표16[specialty_cagr],표16[specialty_category],$B87,표16[end_use_category],K$86),"") | L87: =IFERROR(AVERAGEIFS(표16[specialty_cagr],표16[specialty_category],$B87,표16[end_use_category],L$86),"") -> 0.070838454
B88: Display materials | C88: LCD/OLED 등 평판디스플레이(FPD) 제조에 사용되는 소재·화학 산업 | D88: =_xlfn.XLOOKUP(B88,Sheet8!$A$4:$A$33,Sheet8!$B$4:$B$33) -> 0.029390726 | E88: =IFERROR(AVERAGEIFS(표16[specialty_cagr],표16[specialty_category],$B88,표16[end_use_category],E$86),"") | F88: =IFERROR(AVERAGEIFS(표16[specialty_cagr],표16[specialty_category],$B88,표16[end_use_category],F$86),"") | G88: =IFERROR(AVERAGEIFS(표16[specialty_cagr],표16[specialty_category],$B88,표16[end_use_category],G$86),"") | H88: =IFERROR(AVERAGEIFS(표16[specialty_cagr],표16[specialty_category],$B88,표16[end_use_category],H$86),"") | I88: =IFERROR(AVERAGEIFS(표16[specialty_cagr],표16[specialty_category],$B88,표16[end_use_category],I$86),"") | J88: =IFERROR(AVERAGEIFS(표16[specialty_cagr],표16[specialty_category],$B88,표16[end_use_category],J$86),"") | K88: =IFERROR(AVERAGEIFS(표16[specialty_cagr],표16[specialty_category],$B88,표16[end_use_category],K$86),"") | L88: =IFERROR(AVERAGEIFS(표16[specialty_cagr],표16[specialty_category],$B88,표16[end_use_category],L$86),"") -> 0.029390726
B89: Printed circuit boards and packaging | C89: PCB 및 반도체 패키징 제조에 사용되는 전자화학 소재 산업 | D89: =_xlfn.XLOOKUP(B89,Sheet8!$A$4:$A$33,Sheet8!$B$4:$B$33) -> 0.059094947 | E89: =IFERROR(AVERAGEIFS(표16[specialty_cagr],표16[specialty_category],$B89,표16[end_use_category],E$86),"") | F89: =IFERROR(AVERAGEIFS(표16[specialty_cagr],표16[specialty_category],$B89,표16[end_use_category],F$86),"") | G89: =IFERROR(AVERAGEIFS(표16[specialty_cagr],표16[specialty_category],$B89,표16[end_use_category],G$86),"") | H89: =IFERROR(AVERAGEIFS(표16[specialty_cagr],표16[specialty_category],$B89,표16[end_use_category],H$86),"") | I89: =IFERROR(AVERAGEIFS(표16[specialty_cagr],표16[specialty_category],$B89,표16[end_use_category],I$86),"") | J89: =IFERROR(AVERAGEIFS(표16[specialty_cagr],표16[specialty_category],$B89,표16[end_use_category],J$86),"") | K89: =IFERROR(AVERAGEIFS(표16[specialty_cagr],표16[specialty_category],$B89,표16[end_use_category],K$86),"") | L89: =IFERROR(AVERAGEIFS(표16[specialty_cagr],표16[specialty_category],$B89,표16[end_use_category],L$86),"") -> 0.059094947
B90: Nutraceutical ingredients | C90: 건강기능식품·기능성 식품에 사용되는 기능성 원료 산업 | D90: =_xlfn.XLOOKUP(B90,Sheet8!$A$4:$A$33,Sheet8!$B$4:$B$33) -> 0.040228777 | E90: =IFERROR(AVERAGEIFS(표16[specialty_cagr],표16[specialty_category],$B90,표16[end_use_category],E$86),"") | F90: =IFERROR(AVERAGEIFS(표16[specialty_cagr],표16[specialty_category],$B90,표16[end_use_category],F$86),"") | G90: =IFERROR(AVERAGEIFS(표16[specialty_cagr],표16[specialty_category],$B90,표16[end_use_category],G$86),"") | H90: =IFERROR(AVERAGEIFS(표16[specialty_cagr],표16[specialty_category],$B90,표16[end_use_category],H$86),"") | I90: =IFERROR(AVERAGEIFS(표16[specialty_cagr],표16[specialty_category],$B90,표16[end_use_category],I$86),"") -> 0.040228777 | J90: =IFERROR(AVERAGEIFS(표16[specialty_cagr],표16[specialty_category],$B90,표16[end_use_category],J$86),"") | K90: =IFERROR(AVERAGEIFS(표16[specialty_cagr],표16[specialty_category],$B90,표16[end_use_category],K$86),"") | L90: =IFERROR(AVERAGEIFS(표16[specialty_cagr],표16[specialty_category],$B90,표16[end_use_category],L$86),"")
B91: High-performance thermoplastics | C91: 고온·고내열·고강도 특성을 가진 고성능 엔지니어링 플라스틱 산업 | D91: =_xlfn.XLOOKUP(B91,Sheet8!$A$4:$A$33,Sheet8!$B$4:$B$33) -> 0.034040616 | E91: =IFERROR(AVERAGEIFS(표16[specialty_cagr],표16[specialty_category],$B91,표16[end_use_category],E$86),"") -> 0.034040616 | F91: =IFERROR(AVERAGEIFS(표16[specialty_cagr],표16[specialty_category],$B91,표16[end_use_category],F$86),"") | G91: =IFERROR(AVERAGEIFS(표16[specialty_cagr],표16[specialty_category],$B91,표16[end_use_category],G$86),"") -> 0.034040616 | H91: =IFERROR(AVERAGEIFS(표16[specialty_cagr],표16[specialty_category],$B91,표16[end_use_category],H$86),"") | I91: =IFERROR(AVERAGEIFS(표16[specialty_cagr],표16[specialty_category],$B91,표16[end_use_category],I$86),"") -> 0.034040616 | J91: =IFERROR(AVERAGEIFS(표16[specialty_cagr],표16[specialty_category],$B91,표16[end_use_category],J$86),"") | K91: =IFERROR(AVERAGEIFS(표16[specialty_cagr],표16[specialty_category],$B91,표16[end_use_category],K$86),"") -> 0.034040616 | L91: =IFERROR(AVERAGEIFS(표16[specialty_cagr],표16[specialty_category],$B91,표16[end_use_category],L$86),"") -> 0.034040616
B92: Compounded engineering thermoplastics | C92: 엔지니어링 플라스틱에 첨가제·보강재를 넣어 성능을 맞춤화하는 컴파운딩 산업 | D92: =_xlfn.XLOOKUP(B92,Sheet8!$A$4:$A$33,Sheet8!$B$4:$B$33) -> 0.031736002 | E92: =IFERROR(AVERAGEIFS(표16[specialty_cagr],표16[specialty_category],$B92,표16[end_use_category],E$86),"") | F92: =IFERROR(AVERAGEIFS(표16[specialty_cagr],표16[specialty_category],$B92,표16[end_use_category],F$86),"") | G92: =IFERROR(AVERAGEIFS(표16[specialty_cagr],표16[specialty_category],$B92,표16[end_use_category],G$86),"") -> 0.031736002 | H92: =IFERROR(AVERAGEIFS(표16[specialty_cagr],표16[specialty_category],$B92,표16[end_use_category],H$86),"") | I92: =IFERROR(AVERAGEIFS(표16[specialty_cagr],표16[specialty_category],$B92,표16[end_use_category],I$86),"") | J92: =IFERROR(AVERAGEIFS(표16[specialty_cagr],표16[specialty_category],$B92,표16[end_use_category],J$86),"") | K92: =IFERROR(AVERAGEIFS(표16[specialty_cagr],표16[specialty_category],$B92,표16[end_use_category],K$86),"") -> 0.031736002 | L92: =IFERROR(AVERAGEIFS(표16[specialty_cagr],표16[specialty_category],$B92,표16[end_use_category],L$86),"") -> 0.031736002
B93: Specialty films | C93: 기능성·고성능 플라스틱 필름 산업 | D93: =_xlfn.XLOOKUP(B93,Sheet8!$A$4:$A$33,Sheet8!$B$4:$B$33) -> 0.029377151 | E93: =IFERROR(AVERAGEIFS(표16[specialty_cagr],표16[specialty_category],$B93,표16[end_use_category],E$86),"") | F93: =IFERROR(AVERAGEIFS(표16[specialty_cagr],표16[specialty_category],$B93,표16[end_use_category],F$86),"") -> 0.029377151 | G93: =IFERROR(AVERAGEIFS(표16[specialty_cagr],표16[specialty_category],$B93,표16[end_use_category],G$86),"") | H93: =IFERROR(AVERAGEIFS(표16[specialty_cagr],표16[specialty_category],$B93,표16[end_use_category],H$86),"") | I93: =IFERROR(AVERAGEIFS(표16[specialty_cagr],표16[specialty_category],$B93,표16[end_use_category],I$86),"") -> 0.029377151 | J93: =IFERROR(AVERAGEIFS(표16[specialty_cagr],표16[specialty_category],$B93,표16[end_use_category],J$86),"") -> 0.029377151 | K93: =IFERROR(AVERAGEIFS(표16[specialty_cagr],표16[specialty_category],$B93,표16[end_use_category],K$86),"") | L93: =IFERROR(AVERAGEIFS(표16[specialty_cagr],표16[specialty_category],$B93,표16[end_use_category],L$86),"") -> 0.029377151
B94: Coatings, radiation curable | C94: UV/전자빔(EB)으로 순간 경화되는 특수 코팅·잉크·접착제 산업 | D94: =_xlfn.XLOOKUP(B94,Sheet8!$A$4:$A$33,Sheet8!$B$4:$B$33) -> 0.036406497 | E94: =IFERROR(AVERAGEIFS(표16[specialty_cagr],표16[specialty_category],$B94,표16[end_use_category],E$86),"") | F94: =IFERROR(AVERAGEIFS(표16[specialty_cagr],표16[specialty_category],$B94,표16[end_use_category],F$86),"") -> 0.036406497 | G94: =IFERROR(AVERAGEIFS(표16[specialty_cagr],표16[specialty_category],$B94,표16[end_use_category],G$86),"") | H94: =IFERROR(AVERAGEIFS(표16[specialty_cagr],표16[specialty_category],$B94,표16[end_use_category],H$86),"") | I94: =IFERROR(AVERAGEIFS(표16[specialty_cagr],표16[specialty_category],$B94,표16[end_use_category],I$86),"") | J94: =IFERROR(AVERAGEIFS(표16[specialty_cagr],표16[specialty_category],$B94,표16[end_use_category],J$86),"") | K94: =IFERROR(AVERAGEIFS(표16[specialty_cagr],표16[specialty_category],$B94,표16[end_use_category],K$86),"") -> 0.036406497 | L94: =IFERROR(AVERAGEIFS(표16[specialty_cagr],표16[specialty_category],$B94,표16[end_use_category],L$86),"") -> 0.036406497
B95: Coatings, thermosetting powder | C95: 용제 없이 분말 형태로 도장 후 열경화되는 친환경 코팅 산업 | D95: =_xlfn.XLOOKUP(B95,Sheet8!$A$4:$A$33,Sheet8!$B$4:$B$33) -> 0.032355537 | E95: =IFERROR(AVERAGEIFS(표16[specialty_cagr],표16[specialty_category],$B95,표16[end_use_category],E$86),"") -> 0.032355537 | F95: =IFERROR(AVERAGEIFS(표16[specialty_cagr],표16[specialty_category],$B95,표16[end_use_category],F$86),"") | G95: =IFERROR(AVERAGEIFS(표16[specialty_cagr],표16[specialty_category],$B95,표16[end_use_category],G$86),"") -> 0.032355537 | H95: =IFERROR(AVERAGEIFS(표16[specialty_cagr],표16[specialty_category],$B95,표16[end_use_category],H$86),"") | I95: =IFERROR(AVERAGEIFS(표16[specialty_cagr],표16[specialty_category],$B95,표16[end_use_category],I$86),"") | J95: =IFERROR(AVERAGEIFS(표16[specialty_cagr],표16[specialty_category],$B95,표16[end_use_category],J$86),"") | K95: =IFERROR(AVERAGEIFS(표16[specialty_cagr],표16[specialty_category],$B95,표16[end_use_category],K$86),"") -> 0.032355537 | L95: =IFERROR(AVERAGEIFS(표16[specialty_cagr],표16[specialty_category],$B95,표16[end_use_category],L$86),"")
B96: Coatings, high-performance anticorrosion | C96: 철강·콘크리트·선박을 부식 환경으로부터 보호하는 코팅 산업 | D96: =_xlfn.XLOOKUP(B96,Sheet8!$A$4:$A$33,Sheet8!$B$4:$B$33) -> 0.012810807 | E96: =IFERROR(AVERAGEIFS(표16[specialty_cagr],표16[specialty_category],$B96,표16[end_use_category],E$86),"") -> 0.012810807 | F96: =IFERROR(AVERAGEIFS(표16[specialty_cagr],표16[specialty_category],$B96,표16[end_use_category],F$86),"") | G96: =IFERROR(AVERAGEIFS(표16[specialty_cagr],표16[specialty_category],$B96,표16[end_use_category],G$86),"") | H96: =IFERROR(AVERAGEIFS(표16[specialty_cagr],표16[specialty_category],$B96,표16[end_use_category],H$86),"") -> 0.012810807 | I96: =IFERROR(AVERAGEIFS(표16[specialty_cagr],표16[specialty_category],$B96,표16[end_use_category],I$86),"") | J96: =IFERROR(AVERAGEIFS(표16[specialty_cagr],표16[specialty_category],$B96,표16[end_use_category],J$86),"") | K96: =IFERROR(AVERAGEIFS(표16[specialty_cagr],표16[specialty_category],$B96,표16[end_use_category],K$86),"") -> 0.012810807 | L96: =IFERROR(AVERAGEIFS(표16[specialty_cagr],표16[specialty_category],$B96,표16[end_use_category],L$86),"")
B97: Green power materials | C97: 태양광·풍력 설비 제조에 사용되는 친환경 에너지 소재 산업 | D97: =_xlfn.XLOOKUP(B97,Sheet8!$A$4:$A$33,Sheet8!$B$4:$B$33) -> 0.048304526 | E97: =IFERROR(AVERAGEIFS(표16[specialty_cagr],표16[specialty_category],$B97,표16[end_use_category],E$86),"") | F97: =IFERROR(AVERAGEIFS(표16[specialty_cagr],표16[specialty_category],$B97,표16[end_use_category],F$86),"") | G97: =IFERROR(AVERAGEIFS(표16[specialty_cagr],표16[specialty_category],$B97,표16[end_use_category],G$86),"") | H97: =IFERROR(AVERAGEIFS(표16[specialty_cagr],표16[specialty_category],$B97,표16[end_use_category],H$86),"") -> 0.048304526 | I97: =IFERROR(AVERAGEIFS(표16[specialty_cagr],표16[specialty_category],$B97,표16[end_use_category],I$86),"") | J97: =IFERROR(AVERAGEIFS(표16[specialty_cagr],표16[specialty_category],$B97,표16[end_use_category],J$86),"") | K97: =IFERROR(AVERAGEIFS(표16[specialty_cagr],표16[specialty_category],$B97,표16[end_use_category],K$86),"") | L97: =IFERROR(AVERAGEIFS(표16[specialty_cagr],표16[specialty_category],$B97,표16[end_use_category],L$86),"")
B98: Water management chemicals | C98: 정수·폐수·재이용 공정에 사용되는 수처리 특수화학 산업 | D98: =_xlfn.XLOOKUP(B98,Sheet8!$A$4:$A$33,Sheet8!$B$4:$B$33) -> 0.030939657 | E98: =IFERROR(AVERAGEIFS(표16[specialty_cagr],표16[specialty_category],$B98,표16[end_use_category],E$86),"") -> 0.030939657 | F98: =IFERROR(AVERAGEIFS(표16[specialty_cagr],표16[specialty_category],$B98,표16[end_use_category],F$86),"") | G98: =IFERROR(AVERAGEIFS(표16[specialty_cagr],표16[specialty_category],$B98,표16[end_use_category],G$86),"") | H98: =IFERROR(AVERAGEIFS(표16[specialty_cagr],표16[specialty_category],$B98,표16[end_use_category],H$86),"") -> 0.030939657 | I98: =IFERROR(AVERAGEIFS(표16[specialty_cagr],표16[specialty_category],$B98,표16[end_use_category],I$86),"") | J98: =IFERROR(AVERAGEIFS(표16[specialty_cagr],표16[specialty_category],$B98,표16[end_use_category],J$86),"") -> 0.030939657 | K98: =IFERROR(AVERAGEIFS(표16[specialty_cagr],표16[specialty_category],$B98,표16[end_use_category],K$86),"") -> 0.030939657 | L98: =IFERROR(AVERAGEIFS(표16[specialty_cagr],표16[specialty_category],$B98,표16[end_use_category],L$86),"")
... B116: Emission control | C116: 배출가스 저감 촉매 산업 | D116: =_xlfn.XLOOKUP(B116,Sheet8!$A$4:$A$33,Sheet8!$B$4:$B$33) -> -0.040973241 | E116: =IFERROR(AVERAGEIFS(표16[specialty_cagr],표16[specialty_category],$B116,표16[end_use_category],E$86),"") | F116: =IFERROR(AVERAGEIFS(표16[specialty_cagr],표16[specialty_category],$B116,표16[end_use_category],F$86),"") | G116: =IFERROR(AVERAGEIFS(표16[specialty_cagr],표16[specialty_category],$B116,표16[end_use_category],G$86),"") -> -0.040973241 | H116: =IFERROR(AVERAGEIFS(표16[specialty_cagr],표16[specialty_category],$B116,표16[end_use_category],H$86),"") -> -0.040973241 | I116: =IFERROR(AVERAGEIFS(표16[specialty_cagr],표16[specialty_category],$B116,표16[end_use_category],I$86),"") | J116: =IFERROR(AVERAGEIFS(표16[specialty_cagr],표16[specialty_category],$B116,표16[end_use_category],J$86),"") | K116: =IFERROR(AVERAGEIFS(표16[specialty_cagr],표16[specialty_category],$B116,표16[end_use_category],K$86),"") | L116: =IFERROR(AVERAGEIFS(표16[specialty_cagr],표16[specialty_category],$B116,표16[end_use_category],L$86),"")

Sheet rating
A1: importance | B1: rating
A2: Primary | B2: 0.6
A3: Secondary | B3: 0.3
A4: Niche / Emerging | B4: 0.1
A5: norm_count | B5: 0.25
A6: norm_avg | B6: 0.5
A7: norm_max | B7: 0.25
A8: stategy_12 | B8: 0.7
A9: stategy_50 | B9: 0.3

Sheet Sheet5
B1: =_xlfn.XLOOKUP(B4,표13[end_use_category],표13[end_use_att]) -> 1.1388744 | C1: =_xlfn.XLOOKUP(C4,표13[end_use_category],표13[end_use_att]) -> 2.3451012 | D1: =_xlfn.XLOOKUP(D4,표13[end_use_category],표13[end_use_att]) -> 0.8055753 | E1: =_xlfn.XLOOKUP(E4,표13[end_use_category],표13[end_use_att]) -> 1.5528526 | F1: =_xlfn.XLOOKUP(F4,표13[end_use_category],표13[end_use_att]) -> 4.1622727 | G1: =_xlfn.XLOOKUP(G4,표13[end_use_category],표13[end_use_att]) -> 2.319287 | H1: =_xlfn.XLOOKUP(H4,표13[end_use_category],표13[end_use_att]) -> 2.2155187 | I1: =_xlfn.XLOOKUP(I4,표13[end_use_category],표13[end_use_att]) -> 3.3653125
B2: =(B1-MIN($B$1:$I$1))/(MAX($B$1:$I$1)-MIN($B$1:$I$1))*10 -> 0.99293751 | C2: =(C1-MIN($B$1:$I$1))/(MAX($B$1:$I$1)-MIN($B$1:$I$1))*10 -> 4.5864305 | D2: =(D1-MIN($B$1:$I$1))/(MAX($B$1:$I$1)-MIN($B$1:$I$1))*10 -> 0 | E2: =(E1-MIN($B$1:$I$1))/(MAX($B$1:$I$1)-MIN($B$1:$I$1))*10 -> 2.2262278 | F2: =(F1-MIN($B$1:$I$1))/(MAX($B$1:$I$1)-MIN($B$1:$I$1))*10 -> 10 | G2: =(G1-MIN($B$1:$I$1))/(MAX($B$1:$I$1)-MIN($B$1:$I$1))*10 -> 4.5095268 | H2: =(H1-MIN($B$1:$I$1))/(MAX($B$1:$I$1)-MIN($B$1:$I$1))*10 -> 4.2003887 | I2: =(I1-MIN($B$1:$I$1))/(MAX($B$1:$I$1)-MIN($B$1:$I$1))*10 -> 7.6257608
A3: 최대 : rating | B3: 열 레이블
A4: 행 레이블 | B4: Agriculture | C4: Automotive & Future Mobility | D4: Construction & Infrastructure | E4: Consumer Products & Packaging | F4: Electronics, Semiconductors & Digital Infrastructure | G4: Energy, Power & Utilities | H4: Healthcare & Life Sciences | I4: Industrial Goods & Advanced Manufacturing | J4: 총합계 | L4: material_id | M4: material_name | N4: end_use_att
A5: M002 | C5: 0.3 | D5: 0.6 | E5: 0.6 | J5: 0.6 | L5: M002 | M5: =_xlfn.XLOOKUP(L5,표2[material_id],표2[material_name]) -> HDPE | N5: =SUMPRODUCT($B$2:$I$2,B5:I5) -> 2.7116658
A6: M003 | D6: 0.1 | E6: 0.6 | G6: 0.3 | I6: 0.1 | J6: 0.6 | L6: M003 | M6: =_xlfn.XLOOKUP(L6,표2[material_id],표2[material_name]) -> LDPE | N6: =SUMPRODUCT($B$2:$I$2,B6:I6) -> 3.4511708
A7: M004 | B7: 0.3 | E7: 0.6 | G7: 0.1 | J7: 0.6 | L7: M004 | M7: =_xlfn.XLOOKUP(L7,표2[material_id],표2[material_name]) -> LLDPE | N7: =SUMPRODUCT($B$2:$I$2,B7:I7) -> 2.0845706
A8: M005 | I8: 0.6 | J8: 0.6 | L8: M005 | M8: =_xlfn.XLOOKUP(L8,표2[material_id],표2[material_name]) -> EDC | N8: =SUMPRODUCT($B$2:$I$2,B8:I8) -> 4.5754565
A9: M006 | I9: 0.6 | J9: 0.6 | L9: M006 | M9: =_xlfn.XLOOKUP(L9,표2[material_id],표2[material_name]) -> VCM | N9: =SUMPRODUCT($B$2:$I$2,B9:I9) -> 4.5754565
A10: M007 | D10: 0.6 | E10: 0.3 | G10: 0.3 | H10: 0.1 | I10: 0.1 | J10: 0.6 | L10: M007 | M10: =_xlfn.XLOOKUP(L10,표2[material_id],표2[material_name]) -> PVC | N10: =SUMPRODUCT($B$2:$I$2,B10:I10) -> 3.2033413
A11: M008 | G11: 0.6 | I11: 0.3 | J11: 0.6 | L11: M008 | M11: =_xlfn.XLOOKUP(L11,표2[material_id],표2[material_name]) -> Ethanol | N11: =SUMPRODUCT($B$2:$I$2,B11:I11) -> 4.9934443
A12: M010 | E12: 0.3 | I12: 0.6 | J12: 0.6 | L12: M010 | M12: =_xlfn.XLOOKUP(L12,표2[material_id],표2[material_name]) -> Ethyl acetate | N12: =SUMPRODUCT($B$2:$I$2,B12:I12) -> 5.2433248
A13: M012 | E13: 0.3 | I13: 0.6 | J13: 0.6 | L13: M012 | M13: =_xlfn.XLOOKUP(L13,표2[material_id],표2[material_name]) -> EO | N13: =SUMPRODUCT($B$2:$I$2,B13:I13) -> 5.2433248
A14: M014 | D14: 0.3 | E14: 0.3 | G14: 0.6 | I14: 0.6 | J14: 0.6 | L14: M014 | M14: =_xlfn.XLOOKUP(L14,표2[material_id],표2[material_name]) -> MEA | N14: =SUMPRODUCT($B$2:$I$2,B14:I14) -> 7.9490409
A15: M015 | B15: 0.6 | D15: 0.3 | E15: 0.3 | I15: 0.1 | J15: 0.6 | L15: M015 | M15: =_xlfn.XLOOKUP(L15,표2[material_id],표2[material_name]) -> DEA | N15: =SUMPRODUCT($B$2:$I$2,B15:I15) -> 2.0262069
A16: M016 | D16: 0.6 | E16: 0.6 | I16: 0.3 | J16: 0.6 | L16: M016 | M16: =_xlfn.XLOOKUP(L16,표2[material_id],표2[material_name]) -> TEA | N16: =SUMPRODUCT($B$2:$I$2,B16:I16) -> 3.6234649
A17: M017 | C17: 0.3 | E17: 0.6 | J17: 0.6 | L17: M017 | M17: =_xlfn.XLOOKUP(L17,표2[material_id],표2[material_name]) -> MEG | N17: =SUMPRODUCT($B$2:$I$2,B17:I17) -> 2.7116658
A18: M019 | E18: 0.3 | I18: 0.6 | J18: 0.6 | L18: M019 | M18: =_xlfn.XLOOKUP(L18,표2[material_id],표2[material_name]) -> VAM | N18: =SUMPRODUCT($B$2:$I$2,B18:I18) -> 5.2433248
A19: M021 | C19: 0.1 | E19: 0.6 | I19: 0.6 | J19: 0.6 | L19: M021 | M19: =_xlfn.XLOOKUP(L19,표2[material_id],표2[material_name]) -> AN | N19: =SUMPRODUCT($B$2:$I$2,B19:I19) -> 6.3698362
A20: M022 | C20: 0.3 | D20: 0.3 | E20: 0.6 | F20: 0.6 | I20: 0.3 | J20: 0.6 | L20: M022 | M20: =_xlfn.XLOOKUP(L20,표2[material_id],표2[material_name]) -> ABS | N20: =SUMPRODUCT($B$2:$I$2,B20:I20) -> 10.999394
A21: M023 | C21: 0.1 | E21: 0.6 | H21: 0.1 | I21: 0.6 | J21: 0.6 | L21: M023 | M21: =_xlfn.XLOOKUP(L21,표2[material_id],표2[material_name]) -> SAN | N21: =SUMPRODUCT($B$2:$I$2,B21:I21) -> 6.789875
A22: M024 | C22: 0.6 | G22: 0.3 | H22: 0.6 | I22: 0.3 | J22: 0.6 | L22: M024 | M22: =_xlfn.XLOOKUP(L22,표2[material_id],표2[material_name]) -> NBR | N22: =SUMPRODUCT($B$2:$I$2,B22:I22) -> 8.9126778
A23: M025 | C23: 0.6 | D23: 0.3 | E23: 0.6 | F23: 0.1 | G23: 0.3 | H23: 0.3 | J23: 0.6 | L23: M025 | M23: =_xlfn.XLOOKUP(L23,표2[material_id],표2[material_name]) -> PP | N23: =SUMPRODUCT($B$2:$I$2,B23:I23) -> 7.7005696
A24: M026 | F24: 0.3 | I24: 0.6 | J24: 0.6 | L24: M026 | M24: =_xlfn.XLOOKUP(L24,표2[material_id],표2[material_name]) -> PO | N24: =SUMPRODUCT($B$2:$I$2,B24:I24) -> 7.5754565
A25: M027 | D25: 0.6 | E25: 0.3 | H25: 0.3 | I25: 0.3 | J25: 0.6 | L25: M027 | M25: =_xlfn.XLOOKUP(L25,표2[material_id],표2[material_name]) -> PG | N25: =SUMPRODUCT($B$2:$I$2,B25:I25) -> 4.2157132
A26: M028 | C26: 0.3 | D26: 0.6 | E26: 0.6 | I26: 0.3 | J26: 0.6 | L26: M028 | M26: =_xlfn.XLOOKUP(L26,표2[material_id],표2[material_name]) -> PPG | N26: =SUMPRODUCT($B$2:$I$2,B26:I26) -> 4.999394
A27: M029 | D27: 0.6 | E27: 0.3 | I27: 0.6 | J27: 0.6 | L27: M029 | M27: =_xlfn.XLOOKUP(L27,표2[material_id],표2[material_name]) -> Polyols | N27: =SUMPRODUCT($B$2:$I$2,B27:I27) -> 5.2433248
A28: M030 | C28: 0.3 | D28: 0.6 | E28: 0.6 | G28: 0.1 | H28: 0.1 | I28: 0.3 | J28: 0.6 | L28: M030 | M28: =_xlfn.XLOOKUP(L28,표2[material_id],표2[material_name]) -> PU | N28: =SUMPRODUCT($B$2:$I$2,B28:I28) -> 5.8703856
A29: M031 | E29: 0.6 | I29: 0.6 | J29: 0.6 | L29: M031 | M29: =_xlfn.XLOOKUP(L29,표2[material_id],표2[material_name]) -> Acrylic acid | N29: =SUMPRODUCT($B$2:$I$2,B29:I29) -> 5.9111931
A30: M033 | D30: 0.6 | E30: 0.6 | I30: 0.3 | J30: 0.6 | L30: M033 | M30: =_xlfn.XLOOKUP(L30,표2[material_id],표2[material_name]) -> Acrylate ester | N30: =SUMPRODUCT($B$2:$I$2,B30:I30) -> 3.6234649
A31: M034 | B31: 0.1 | E31: 0.6 | H31: 0.3 | J31: 0.6 | L31: M034 | M31: =_xlfn.XLOOKUP(L31,표2[material_id],표2[material_name]) -> SAP | N31: =SUMPRODUCT($B$2:$I$2,B31:I31) -> 2.695147
A32: M035 | I32: 0.6 | J32: 0.6 | L32: M035 | M32: =_xlfn.XLOOKUP(L32,표2[material_id],표2[material_name]) -> n-Butyraldehyde | N32: =SUMPRODUCT($B$2:$I$2,B32:I32) -> 4.5754565
A33: M036 | D33: 0.6 | I33: 0.6 | J33: 0.6 | L33: M036 | M33: =_xlfn.XLOOKUP(L33,표2[material_id],표2[material_name]) -> 2-Ethylhexanol | N33: =SUMPRODUCT($B$2:$I$2,B33:I33) -> 4.5754565
A34: M037 | I34: 0.6 | J34: 0.6 | L34: M037 | M34: =_xlfn.XLOOKUP(L34,표2[material_id],표2[material_name]) -> n-Butanol | N34: =SUMPRODUCT($B$2:$I$2,B34:I34) -> 4.5754565
A35: M038 | I35: 0.6 | J35: 0.6 | L35: M038 | M35: =_xlfn.XLOOKUP(L35,표2[material_id],표2[material_name]) -> n-Butyl acetate | N35: =SUMPRODUCT($B$2:$I$2,B35:I35) -> 4.5754565
A36: M039 | I36: 0.6 | J36: 0.6 | L36: M039 | M36: =_xlfn.XLOOKUP(L36,표2[material_id],표2[material_name]) -> Isobutanol | N36: =SUMPRODUCT($B$2:$I$2,B36:I36) -> 4.5754565
A37: M040 | I37: 0.6 | J37: 0.6 | L37: M040 | M37: =_xlfn.XLOOKUP(L37,표2[material_id],표2[material_name]) -> Isobutyl acetate | N37: =SUMPRODUCT($B$2:$I$2,B37:I37) -> 4.5754565
A38: M041 | E38: 0.3 | F38: 0.1 | H38: 0.3 | I38: 0.6 | J38: 0.6 | L38: M041 | M38: =_xlfn.XLOOKUP(L38,표2[material_id],표2[material_name]) -> IPA | N38: =SUMPRODUCT($B$2:$I$2,B38:I38) -> 7.5034414
A39: M042 | E39: 0.1 | I39: 0.6 | J39: 0.6 | L39: M042 | M39: =_xlfn.XLOOKUP(L39,표2[material_id],표2[material_name]) -> Isopropyl acetate | N39: =SUMPRODUCT($B$2:$I$2,B39:I39) -> 4.7980792
A40: M043 | I40: 0.6 | J40: 0.6 | L40: M043 | M40: =_xlfn.XLOOKUP(L40,표2[material_id],표2[material_name]) -> Butadiene | N40: =SUMPRODUCT($B$2:$I$2,B40:I40) -> 4.5754565
...

Sheet app_master
A1: material_id | B1: app_id | C1: end_use_id | D1: rating | E1: material_name | F1: raw application | G1: application_taxonomy | H1: end_use_industry | I1: importance | J1: reasoning | K1: taxonomy_action | L1: source
A2: =_xlfn.XLOOKUP(표14[[#This Row],[material_name]],표2[material_name],표2[material_id]) -> M002 | B2: =_xlfn.XLOOKUP(표14[[#This Row],[application_taxonomy]],표11[application_taxonomy],표11[app_id]) -> A06 | C2: =_xlfn.XLOOKUP(표14[[#This Row],[end_use_industry]],표13[end_use_category],표13[end_use_id]) -> E02 | D2: =_xlfn.XLOOKUP(표14[[#This Row],[importance]],표15[importance],표15[rating]) -> 0.6 | E2: HDPE | F2: Blow molding | G2: Rigid packaging | H2: Consumer Products & Packaging | I2: Primary | J2: 2024년 27%로 최대 용도, 병·용기 중심 | K2: Existing
A3: =_xlfn.XLOOKUP(표14[[#This Row],[material_name]],표2[material_name],표2[material_id]) -> M002 | B3: =_xlfn.XLOOKUP(표14[[#This Row],[application_taxonomy]],표11[application_taxonomy],표11[app_id]) -> A05 | C3: =_xlfn.XLOOKUP(표14[[#This Row],[end_use_industry]],표13[end_use_category],표13[end_use_id]) -> E02 | D3: =_xlfn.XLOOKUP(표14[[#This Row],[importance]],표15[importance],표15[rating]) -> 0.6 | E3: HDPE | F3: Film and sheet | G3: Flexible packaging | H3: Consumer Products & Packaging | I3: Primary | J3: 2024년 24%로 blow molding과 함께 핵심 수요 | K3: Existing
A4: =_xlfn.XLOOKUP(표14[[#This Row],[material_name]],표2[material_name],표2[material_id]) -> M002 | B4: =_xlfn.XLOOKUP(표14[[#This Row],[application_taxonomy]],표11[application_taxonomy],표11[app_id]) -> A09 | C4: =_xlfn.XLOOKUP(표14[[#This Row],[end_use_industry]],표13[end_use_category],표13[end_use_id]) -> E01 | D4: =_xlfn.XLOOKUP(표14[[#This Row],[importance]],표15[importance],표15[rating]) -> 0.6 | E4: HDPE | F4: Pipe and extrusion | G4: Pipe & fluid conveyance | H4: Construction & Infrastructure | I4: Primary | J4: 2024년 20%, 인프라·배관 수요와 직접 연결 | K4: Existing
A5: =_xlfn.XLOOKUP(표14[[#This Row],[material_name]],표2[material_name],표2[material_id]) -> M002 | B5: =_xlfn.XLOOKUP(표14[[#This Row],[application_taxonomy]],표11[application_taxonomy],표11[app_id]) -> A04 | C5: =_xlfn.XLOOKUP(표14[[#This Row],[end_use_industry]],표13[end_use_category],표13[end_use_id]) -> E02 | D5: =_xlfn.XLOOKUP(표14[[#This Row],[importance]],표15[importance],표15[rating]) -> 0.3 | E5: HDPE | F5: Injection molding | G5: Polymer resin / molding material | H5: Consumer Products & Packaging | I5: Secondary | J5: 2024년 17%로 주요 성형 application | K5: Existing
A6: =_xlfn.XLOOKUP(표14[[#This Row],[material_name]],표2[material_name],표2[material_id]) -> M002 | B6: =_xlfn.XLOOKUP(표14[[#This Row],[application_taxonomy]],표11[application_taxonomy],표11[app_id]) -> A09 | C6: =_xlfn.XLOOKUP(표14[[#This Row],[end_use_industry]],표13[end_use_category],표13[end_use_id]) -> E01 | D6: =_xlfn.XLOOKUP(표14[[#This Row],[importance]],표15[importance],표15[rating]) -> 0.3 | E6: HDPE | F6: Water supply and durable storage containers | G6: Pipe & fluid conveyance | H6: Construction & Infrastructure | I6: Secondary | J6: 물 공급·저장용 내구재로 사용 | K6: Existing
A7: =_xlfn.XLOOKUP(표14[[#This Row],[material_name]],표2[material_name],표2[material_id]) -> M002 | B7: =_xlfn.XLOOKUP(표14[[#This Row],[application_taxonomy]],표11[application_taxonomy],표11[app_id]) -> A16 | C7: =_xlfn.XLOOKUP(표14[[#This Row],[end_use_industry]],표13[end_use_category],표13[end_use_id]) -> E03 | D7: =_xlfn.XLOOKUP(표14[[#This Row],[importance]],표15[importance],표15[rating]) -> 0.3 | E7: HDPE | F7: Automotive fuel tanks and reservoirs | G7: Automotive components & lightweighting | H7: Automotive & Future Mobility | I7: Secondary | J7: 자동차 연료탱크·저장용기 적용 | K7: Existing
A8: =_xlfn.XLOOKUP(표14[[#This Row],[material_name]],표2[material_name],표2[material_id]) -> M003 | B8: =_xlfn.XLOOKUP(표14[[#This Row],[application_taxonomy]],표11[application_taxonomy],표11[app_id]) -> A05 | C8: =_xlfn.XLOOKUP(표14[[#This Row],[end_use_industry]],표13[end_use_category],표13[end_use_id]) -> E02 | D8: =_xlfn.XLOOKUP(표14[[#This Row],[importance]],표15[importance],표15[rating]) -> 0.6 | E8: LDPE | F8: Film and sheet | G8: Flexible packaging | H8: Consumer Products & Packaging | I8: Primary | J8: 2024년 수요의 69%로 최대 용도 | K8: Existing
A9: =_xlfn.XLOOKUP(표14[[#This Row],[material_name]],표2[material_name],표2[material_id]) -> M003 | B9: =_xlfn.XLOOKUP(표14[[#This Row],[application_taxonomy]],표11[application_taxonomy],표11[app_id]) -> A07 | C9: =_xlfn.XLOOKUP(표14[[#This Row],[end_use_industry]],표13[end_use_category],표13[end_use_id]) -> E02 | D9: =_xlfn.XLOOKUP(표14[[#This Row],[importance]],표15[importance],표15[rating]) -> 0.3 | E9: LDPE | F9: Extrusion coating | G9: Barrier packaging | H9: Consumer Products & Packaging | I9: Secondary | J9: 포장재 코팅 및 배리어 용도에서 중요한 2차 application | K9: Existing
A10: =_xlfn.XLOOKUP(표14[[#This Row],[material_name]],표2[material_name],표2[material_id]) -> M003 | B10: =_xlfn.XLOOKUP(표14[[#This Row],[application_taxonomy]],표11[application_taxonomy],표11[app_id]) -> A13 | C10: =_xlfn.XLOOKUP(표14[[#This Row],[end_use_industry]],표13[end_use_category],표13[end_use_id]) -> E04 | D10: =_xlfn.XLOOKUP(표14[[#This Row],[importance]],표15[importance],표15[rating]) -> 0.3 | E10: LDPE | F10: Wire and cable | G10: Electrical insulation | H10: Energy, Power & Utilities | I10: Secondary | J10: 절연·재킷용으로 사용되나 비중은 제한적 | K10: Existing
A11: =_xlfn.XLOOKUP(표14[[#This Row],[material_name]],표2[material_name],표2[material_id]) -> M003 | B11: =_xlfn.XLOOKUP(표14[[#This Row],[application_taxonomy]],표11[application_taxonomy],표11[app_id]) -> A04 | C11: =_xlfn.XLOOKUP(표14[[#This Row],[end_use_industry]],표13[end_use_category],표13[end_use_id]) -> E02 | D11: =_xlfn.XLOOKUP(표14[[#This Row],[importance]],표15[importance],표15[rating]) -> 0.3 | E11: LDPE | F11: Injection molding | G11: Polymer resin / molding material | H11: Consumer Products & Packaging | I11: Secondary | J11: 캡, 완구, 생활용품 등 성형품 용도 | K11: Existing
A12: =_xlfn.XLOOKUP(표14[[#This Row],[material_name]],표2[material_name],표2[material_id]) -> M003 | B12: =_xlfn.XLOOKUP(표14[[#This Row],[application_taxonomy]],표11[application_taxonomy],표11[app_id]) -> A09 | C12: =_xlfn.XLOOKUP(표14[[#This Row],[end_use_industry]],표13[end_use_category],표13[end_use_id]) -> E01 | D12: =_xlfn.XLOOKUP(표14[[#This Row],[importance]],표15[importance],표15[rating]) -> 0.1 | E12: LDPE | F12: Pipe and extrusion | G12: Pipe & fluid conveyance | H12: Construction & Infrastructure | I12: Niche / Emerging | J12: 관·튜빙 용도는 2024년 약 2%로 제한적 | K12: Existing
A13: =_xlfn.XLOOKUP(표14[[#This Row],[material_name]],표2[material_name],표2[material_id]) -> M003 | B13: =_xlfn.XLOOKUP(표14[[#This Row],[application_taxonomy]],표11[application_taxonomy],표11[app_id]) -> A20 | C13: =_xlfn.XLOOKUP(표14[[#This Row],[end_use_industry]],표13[end_use_category],표13[end_use_id]) -> E07 | D13: =_xlfn.XLOOKUP(표14[[#This Row],[importance]],표15[importance],표15[rating]) -> 0.1 | E13: LDPE | F13: Adhesives and sealants | G13: Adhesive bonding | H13: Industrial Goods & Advanced Manufacturing | I13: Niche / Emerging | J13: EVA계 hot-melt adhesive 등 특수 용도 | K13: Existing
... A58: =_xlfn.XLOOKUP(표14[[#This Row],[material_name]],표2[material_name],표2[material_id]) -> M019 | B58: =_xlfn.XLOOKUP(표14[[#This Row],[application_taxonomy]],표11[application_taxonomy],표11[app_id]) -> A01 | C58: =_xlfn.XLOOKUP(표14[[#This Row],[end_use_industry]],표13[end_use_category],표13[end_use_id]) -> E07 | D58: =_xlfn.XLOOKUP(표14[[#This Row],[importance]],표15[importance],표15[rating]) -> 0.6 | E58: VAM | F58: Polyvinyl acetate (PVA) | G58: Major chemical intermediate | H58: Industrial Goods & Advanced Manufacturing | I58: Primary | J58: 2024년 VAM 소비의 28%로 주요 polymer 원료 | K58: Existing
A59: =_xlfn.XLOOKUP(표14[[#This Row],[material_name]],표2[material_name],표2[material_id]) -> M019 | B59: =_xlfn.XLOOKUP(표14[[#This Row],[application_taxonomy]],표11[application_taxonomy],표11[app_id]) -> #N/A | C59: =_xlfn.XLOOKUP(표14[[#This Row],[end_use_industry]],표13[end_use_category],표13[end_use_id]) -> E07 | D59: =_xlfn.XLOOKUP(표14[[#This Row],[importance]],표15[importance],표15[rating]) -> 0.3 | E59: VAM | F59: Ethylene-vinyl acetate (EVA) | G59: 0 | H59: Industrial Goods & Advanced Manufacturing | I59: Secondary | J59: EVA/VAE 수요가 빠르게 성장하는 VAM downstream | K59: Existing
A60: =_xlfn.XLOOKUP(표14[[#This Row],[material_name]],표2[material_name],표2[material_id]) -> M019 | B60: =_xlfn.XLOOKUP(표14[[#This Row],[application_taxonomy]],표11[application_taxonomy],표11[app_id]) -> A01 | C60: =_xlfn.XLOOKUP(표14[[#This Row],[end_use_industry]],표13[end_use_category],표13[end_use_id]) -> E02 | D60: =_xlfn.XLOOKUP(표14[[#This Row],[importance]],표15[importance],표15[rating]) -> 0.3 | E60: VAM | F60: Ethylene-vinyl alcohol (EVOH) | G60: Major chemical intermediate | H60: Consumer Products & Packaging | I60: Secondary | J60: EVOH barrier resin으로 연결되는 comonomer 용도 | K60: Existing
A61: =_xlfn.XLOOKUP(표14[[#This Row],[material_name]],표2[material_name],표2[material_id]) -> M021 | B61: =_xlfn.XLOOKUP(표14[[#This Row],[application_taxonomy]],표11[application_taxonomy],표11[app_id]) -> A01 | C61: =_xlfn.XLOOKUP(표14[[#This Row],[end_use_industry]],표13[end_use_category],표13[end_use_id]) -> E07 | D61: =_xlfn.XLOOKUP(표14[[#This Row],[importance]],표15[importance],표15[rating]) -> 0.6 | E61: AN | F61: ABS resins | G61: Major chemical intermediate | H61: Industrial Goods & Advanced Manufacturing | I61: Primary | J61: AN 최대 수요처로 2024년 약 35% 차지 | K61: Existing
A62: =_xlfn.XLOOKUP(표14[[#This Row],[material_name]],표2[material_name],표2[material_id]) -> M021 | B62: =_xlfn.XLOOKUP(표14[[#This Row],[application_taxonomy]],표11[application_taxonomy],표11[app_id]) -> A02 | C62: =_xlfn.XLOOKUP(표14[[#This Row],[end_use_industry]],표13[end_use_category],표13[end_use_id]) -> E07 | D62: =_xlfn.XLOOKUP(표14[[#This Row],[importance]],표15[importance],표15[rating]) -> 0.6 | E62: AN | F62: Acrylamide | G62: Specialty chemical intermediate | H62: Industrial Goods & Advanced Manufacturing | I62: Primary | J62: PAM 및 wastewater treatment로 연결되는 주요 수요처 | K62: Existing
A63: =_xlfn.XLOOKUP(표14[[#This Row],[material_name]],표2[material_name],표2[material_id]) -> M021 | B63: =_xlfn.XLOOKUP(표14[[#This Row],[application_taxonomy]],표11[application_taxonomy],표11[app_id]) -> A03 | C63: =_xlfn.XLOOKUP(표14[[#This Row],[end_use_industry]],표13[end_use_category],표13[end_use_id]) -> E02 | D63: =_xlfn.XLOOKUP(표14[[#This Row],[importance]],표15[importance],표15[rating]) -> 0.6 | E63: AN | F63: Acrylic fibers | G63: Reactive monomer / comonomer | H63: Consumer Products & Packaging | I63: Primary | J63: 역사적 핵심 수요처이나 polyester와 경쟁으로 성장 둔화 | K63: Existing
A64: =_xlfn.XLOOKUP(표14[[#This Row],[material_name]],표2[material_name],표2[material_id]) -> M021 | B64: =_xlfn.XLOOKUP(표14[[#This Row],[application_taxonomy]],표11[application_taxonomy],표11[app_id]) -> A01 | C64: =_xlfn.XLOOKUP(표14[[#This Row],[end_use_industry]],표13[end_use_category],표13[end_use_id]) -> E07 | D64: =_xlfn.XLOOKUP(표14[[#This Row],[importance]],표15[importance],표15[rating]) -> 0.3 | E64: AN | F64: SAN resins | G64: Major chemical intermediate | H64: Industrial Goods & Advanced Manufacturing | I64: Secondary | J64: SAN 및 ABS/ASA/AES chain으로 연결 | K64: Existing
A65: =_xlfn.XLOOKUP(표14[[#This Row],[material_name]],표2[material_name],표2[material_id]) -> M021 | B65: =_xlfn.XLOOKUP(표14[[#This Row],[application_taxonomy]],표11[application_taxonomy],표11[app_id]) -> A01 | C65: =_xlfn.XLOOKUP(표14[[#This Row],[end_use_industry]],표13[end_use_category],표13[end_use_id]) -> E03 | D65: =_xlfn.XLOOKUP(표14[[#This Row],[importance]],표15[importance],표15[rating]) -> 0.1 | E65: AN | F65: PAN-based carbon fiber | G65: Major chemical intermediate | H65: Automotive & Future Mobility | I65: Niche / Emerging | J65: carbon fiber 성장성이 있으나 현재 비중은 작음 | K65: Existing
A66: =_xlfn.XLOOKUP(표14[[#This Row],[material_name]],표2[material_name],표2[material_id]) -> M022 | B66: =_xlfn.XLOOKUP(표14[[#This Row],[application_taxonomy]],표11[application_taxonomy],표11[app_id]) -> A04 | C66: =_xlfn.XLOOKUP(표14[[#This Row],[end_use_industry]],표13[end_use_category],표13[end_use_id]) -> E02 | D66: =_xlfn.XLOOKUP(표14[[#This Row],[importance]],표15[importance],표15[rating]) -> 0.6 | E66: ABS | F66: Appliances | G66: Polymer resin / molding material | H66: Consumer Products & Packaging | I66: Primary | J66: 2025년 ABS 최대 end use, 약 42% | K66: Existing
A67: =_xlfn.XLOOKUP(표14[[#This Row],[material_name]],표2[material_name],표2[material_id]) -> M022 | B67: =_xlfn.XLOOKUP(표14[[#This Row],[application_taxonomy]],표11[application_taxonomy],표11[app_id]) -> A40 | C67: =_xlfn.XLOOKUP(표14[[#This Row],[end_use_industry]],표13[end_use_category],표13[end_use_id]) -> E08 | D67: =_xlfn.XLOOKUP(표14[[#This Row],[importance]],표15[importance],표15[rating]) -> 0.6 | E67: ABS | F67: Electrical/electronic applications | G67: Electronic chemicals & materials | H67: Electronics, Semiconductors & Digital Infrastructure | I67: Primary | J67: 2025년 약 21%로 주요 소비처 | K67: Existing
A68: =_xlfn.XLOOKUP(표14[[#This Row],[material_name]],표2[material_name],표2[material_id]) -> M022 | B68: =_xlfn.XLOOKUP(표14[[#This Row],[application_taxonomy]],표11[application_taxonomy],표11[app_id]) -> A16 | C68: =_xlfn.XLOOKUP(표14[[#This Row],[end_use_industry]],표13[end_use_category],표13[end_use_id]) -> E03 | D68: =_xlfn.XLOOKUP(표14[[#This Row],[importance]],표15[importance],표15[rating]) -> 0.3 | E68: ABS | F68: Transportation | G68: Automotive components & lightweighting | H68: Automotive & Future Mobility | I68: Secondary | J68: 경량화와 내충격성이 요구되는 자동차 부품용 | K68: Existing
A69: =_xlfn.XLOOKUP(표14[[#This Row],[material_name]],표2[material_name],표2[material_id]) -> M022 | B69: =_xlfn.XLOOKUP(표14[[#This Row],[application_taxonomy]],표11[application_taxonomy],표11[app_id]) -> A10 | C69: =_xlfn.XLOOKUP(표14[[#This Row],[end_use_industry]],표13[end_use_category],표13[end_use_id]) -> E01 | D69: =_xlfn.XLOOKUP(표14[[#This Row],[importance]],표15[importance],표15[rating]) -> 0.3 | E69: ABS | F69: Building and construction | G69: Building materials & profiles | H69: Construction & Infrastructure | I69: Secondary | J69: 건축·건설용 성형 소재 수요 | K69: Existing
A70: =_xlfn.XLOOKUP(표14[[#This Row],[material_name]],표2[material_name],표2[material_id]) -> M022 | B70: =_xlfn.XLOOKUP(표14[[#This Row],[application_taxonomy]],표11[application_taxonomy],표11[app_id]) -> A38 | C70: =_xlfn.XLOOKUP(표14[[#This Row],[end_use_industry]],표13[end_use_category],표13[end_use_id]) -> E07 | D70: =_xlfn.XLOOKUP(표14[[#This Row],[importance]],표15[importance],표15[rating]) -> 0.3 | E70: ABS | F70: PC/ABS, PBT/ABS, polyamide/ABS blends | G70: Polymer modification & additives | H70: Industrial Goods & Advanced Manufacturing | I70: Secondary | J70: 다른 engineering plastics와 blend되어 물성 보완 | K70: Existing
A71: =_xlfn.XLOOKUP(표14[[#This Row],[material_name]],표2[material_name],표2[material_id]) -> M023 | B71: =_xlfn.XLOOKUP(표14[[#This Row],[application_taxonomy]],표11[application_taxonomy],표11[app_id]) -> A04 | C71: =_xlfn.XLOOKUP(표14[[#This Row],[end_use_industry]],표13[end_use_category],표13[end_use_id]) -> E02 | D71: =_xlfn.XLOOKUP(표14[[#This Row],[importance]],표15[importance],표15[rating]) -> 0.6 | E71: SAN | F71: Housewares | G71: Polymer resin / molding material | H71: Consumer Products & Packaging | I71: Primary | J71: 투명성, 내화학성, 내열성이 필요한 생활용품 주요 용도 | K71: Existing
... A105: =_xlfn.XLOOKUP(표14[[#This Row],[material_name]],표2[material_name],표2[material_id]) -> M027 | B105: =_xlfn.XLOOKUP(표14[[#This Row],[application_taxonomy]],표11[application_taxonomy],표11[app_id]) -> A01 | C105: =_xlfn.XLOOKUP(표14[[#This Row],[end_use_industry]],표13[end_use_category],표13[end_use_id]) -> E07 | D105: =_xlfn.XLOOKUP(표14[[#This Row],[importance]],표15[importance],표15[rating]) -> 0.3 | E105: PG | F105: Polyurethanes | G105: Major chemical intermediate | H105: Industrial Goods & Advanced Manufacturing | I105: Secondary | J105: polyurethane chain으로 연결되는 산업용 PG 수요 | K105: Existing
A106: =_xlfn.XLOOKUP(표14[[#This Row],[material_name]],표2[material_name],표2[material_id]) -> M028 | B106: =_xlfn.XLOOKUP(표14[[#This Row],[application_taxonomy]],표11[application_taxonomy],표11[app_id]) -> A01 | C106: =_xlfn.XLOOKUP(표14[[#This Row],[end_use_industry]],표13[end_use_category],표13[end_use_id]) -> E02 | D106: =_xlfn.XLOOKUP(표14[[#This Row],[importance]],표15[importance],표15[rating]) -> 0.6 | E106: PPG | F106: Flexible PU foams | G106: Major chemical intermediate | H106: Consumer Products & Packaging | I106: Primary | J106: bedding, furniture, transportation cushioning으로 연결되는 핵심 polyol route | K106: Existing | L106: GPT
A107: =_xlfn.XLOOKUP(표14[[#This Row],[material_name]],표2[material_name],표2[material_id]) -> M028 | B107: =_xlfn.XLOOKUP(표14[[#This Row],[application_taxonomy]],표11[application_taxonomy],표11[app_id]) -> A01 | C107: =_xlfn.XLOOKUP(표14[[#This Row],[end_use_industry]],표13[end_use_category],표13[end_use_id]) -> E01 | D107: =_xlfn.XLOOKUP(표14[[#This Row],[importance]],표15[importance],표15[rating]) -> 0.6 | E107: PPG | F107: Rigid PU foams | G107: Major chemical intermediate | H107: Construction & Infrastructure | I107: Primary | J107: 건축·냉장·배관 insulation용 PU foam 원료 | K107: Existing | L107: GPT
A108: =_xlfn.XLOOKUP(표14[[#This Row],[material_name]],표2[material_name],표2[material_id]) -> M028 | B108: =_xlfn.XLOOKUP(표14[[#This Row],[application_taxonomy]],표11[application_taxonomy],표11[app_id]) -> A01 | C108: =_xlfn.XLOOKUP(표14[[#This Row],[end_use_industry]],표13[end_use_category],표13[end_use_id]) -> E03 | D108: =_xlfn.XLOOKUP(표14[[#This Row],[importance]],표15[importance],표15[rating]) -> 0.3 | E108: PPG | F108: Nonfoam PU applications | G108: Major chemical intermediate | H108: Automotive & Future Mobility | I108: Secondary | J108: cast elastomers, tubing, hoses, fascias, shoe soles 등 | K108: Existing | L108: GPT
A109: =_xlfn.XLOOKUP(표14[[#This Row],[material_name]],표2[material_name],표2[material_id]) -> M028 | B109: =_xlfn.XLOOKUP(표14[[#This Row],[application_taxonomy]],표11[application_taxonomy],표11[app_id]) -> A01 | C109: =_xlfn.XLOOKUP(표14[[#This Row],[end_use_industry]],표13[end_use_category],표13[end_use_id]) -> E07 | D109: =_xlfn.XLOOKUP(표14[[#This Row],[importance]],표15[importance],표15[rating]) -> 0.3 | E109: PPG | F109: Adhesives and sealants | G109: Major chemical intermediate | H109: Industrial Goods & Advanced Manufacturing | I109: Secondary | J109: PU adhesive/sealant chain으로 연결 | K109: Existing | L109: GPT
A110: =_xlfn.XLOOKUP(표14[[#This Row],[material_name]],표2[material_name],표2[material_id]) -> M028 | B110: =_xlfn.XLOOKUP(표14[[#This Row],[application_taxonomy]],표11[application_taxonomy],표11[app_id]) -> A01 | C110: =_xlfn.XLOOKUP(표14[[#This Row],[end_use_industry]],표13[end_use_category],표13[end_use_id]) -> E07 | D110: =_xlfn.XLOOKUP(표14[[#This Row],[importance]],표15[importance],표15[rating]) -> 0.3 | E110: PPG | F110: Surface coatings | G110: Major chemical intermediate | H110: Industrial Goods & Advanced Manufacturing | I110: Secondary | J110: PU surface coating application 포함 | K110: Existing | L110: GPT
A111: =_xlfn.XLOOKUP(표14[[#This Row],[material_name]],표2[material_name],표2[material_id]) -> M029 | B111: =_xlfn.XLOOKUP(표14[[#This Row],[application_taxonomy]],표11[application_taxonomy],표11[app_id]) -> A01 | C111: =_xlfn.XLOOKUP(표14[[#This Row],[end_use_industry]],표13[end_use_category],표13[end_use_id]) -> E01 | D111: =_xlfn.XLOOKUP(표14[[#This Row],[importance]],표15[importance],표15[rating]) -> 0.6 | E111: Polyols | F111: Rigid PU/PIR foam | G111: Major chemical intermediate | H111: Construction & Infrastructure | I111: Primary | J111: polyester polyol 최대 성장·핵심 용도, building insulation 중심 | K111: Existing
A112: =_xlfn.XLOOKUP(표14[[#This Row],[material_name]],표2[material_name],표2[material_id]) -> M029 | B112: =_xlfn.XLOOKUP(표14[[#This Row],[application_taxonomy]],표11[application_taxonomy],표11[app_id]) -> A01 | C112: =_xlfn.XLOOKUP(표14[[#This Row],[end_use_industry]],표13[end_use_category],표13[end_use_id]) -> E07 | D112: =_xlfn.XLOOKUP(표14[[#This Row],[importance]],표15[importance],표15[rating]) -> 0.6 | E112: Polyols | F112: PU elastomers / TPU | G112: Major chemical intermediate | H112: Industrial Goods & Advanced Manufacturing | I112: Primary | J112: nonfoam application 중 elastomer가 주요 수요처 | K112: Existing
A113: =_xlfn.XLOOKUP(표14[[#This Row],[material_name]],표2[material_name],표2[material_id]) -> M029 | B113: =_xlfn.XLOOKUP(표14[[#This Row],[application_taxonomy]],표11[application_taxonomy],표11[app_id]) -> A01 | C113: =_xlfn.XLOOKUP(표14[[#This Row],[end_use_industry]],표13[end_use_category],표13[end_use_id]) -> E07 | D113: =_xlfn.XLOOKUP(표14[[#This Row],[importance]],표15[importance],표15[rating]) -> 0.3 | E113: Polyols | F113: Surface coatings | G113: Major chemical intermediate | H113: Industrial Goods & Advanced Manufacturing | I113: Secondary | J113: aircraft, bridge, automotive coating 등에 사용 | K113: Existing
A114: =_xlfn.XLOOKUP(표14[[#This Row],[material_name]],표2[material_name],표2[material_id]) -> M029 | B114: =_xlfn.XLOOKUP(표14[[#This Row],[application_taxonomy]],표11[application_taxonomy],표11[app_id]) -> A01 | C114: =_xlfn.XLOOKUP(표14[[#This Row],[end_use_industry]],표13[end_use_category],표13[end_use_id]) -> E07 | D114: =_xlfn.XLOOKUP(표14[[#This Row],[importance]],표15[importance],표15[rating]) -> 0.3 | E114: Polyols | F114: Adhesives and sealants | G114: Major chemical intermediate | H114: Industrial Goods & Advanced Manufacturing | I114: Secondary | J114: PU hot-melt adhesive 및 sealant 원료 | K114: Existing
A115: =_xlfn.XLOOKUP(표14[[#This Row],[material_name]],표2[material_name],표2[material_id]) -> M029 | B115: =_xlfn.XLOOKUP(표14[[#This Row],[application_taxonomy]],표11[application_taxonomy],표11[app_id]) -> A01 | C115: =_xlfn.XLOOKUP(표14[[#This Row],[end_use_industry]],표13[end_use_category],표13[end_use_id]) -> E02 | D115: =_xlfn.XLOOKUP(표14[[#This Row],[importance]],표15[importance],표15[rating]) -> 0.3 | E115: Polyols | F115: Flexible foams | G115: Major chemical intermediate | H115: Consumer Products & Packaging | I115: Secondary | J115: textile laminates, bedding 등 specialty flexible foam | K115: Existing
A116: =_xlfn.XLOOKUP(표14[[#This Row],[material_name]],표2[material_name],표2[material_id]) -> M030 | B116: =_xlfn.XLOOKUP(표14[[#This Row],[application_taxonomy]],표11[application_taxonomy],표11[app_id]) -> A17 | C116: =_xlfn.XLOOKUP(표14[[#This Row],[end_use_industry]],표13[end_use_category],표13[end_use_id]) -> E02 | D116: =_xlfn.XLOOKUP(표14[[#This Row],[importance]],표15[importance],표15[rating]) -> 0.6 | E116: PU | F116: Flexible foams: bedding, furniture, transportation | G116: Cushioning & comfort materials | H116: Consumer Products & Packaging | I116: Primary | J116: flexible PU foam은 cushioning 소재로 대량 사용 | K116: Existing
A117: =_xlfn.XLOOKUP(표14[[#This Row],[material_name]],표2[material_name],표2[material_id]) -> M030 | B117: =_xlfn.XLOOKUP(표14[[#This Row],[application_taxonomy]],표11[application_taxonomy],표11[app_id]) -> A12 | C117: =_xlfn.XLOOKUP(표14[[#This Row],[end_use_industry]],표13[end_use_category],표13[end_use_id]) -> E01 | D117: =_xlfn.XLOOKUP(표14[[#This Row],[importance]],표15[importance],표15[rating]) -> 0.6 | E117: PU | F117: Rigid PU/PIR foams: construction and industrial insulation | G117: Thermal insulation | H117: Construction & Infrastructure | I117: Primary | J117: rigid foam의 핵심은 construction 및 industrial insulation | K117: Existing
...

Sheet end_use_id
A1: end_use_id | B1: end_use_category | C1: Chemical Related Demand | D1: specialty_count | E1: specialty_avg_cagr | F1: specialty_max_cagr | G1: norm_count | H1: norm_avg | I1: norm_max | J1: specialty_opp | K1: stategy_12 | L1: stategy_50 | M1: stategy_opp | N1: ind_growth | O1: end_use_att
A2: E01 | B2: Construction & Infrastructure | C2: PVC pipe, flooring, insulation, coatings, construction chemicals | D2: =COUNTIF(표16[end_use_category],표13[[#This Row],[end_use_category]]) -> 7 | E2: =AVERAGEIF(표16[end_use_category],표13[[#This Row],[end_use_category]],표16[specialty_cagr]) -> 0.025588715 | F2: =_xlfn.MAXIFS(표16[specialty_cagr],표16[end_use_category],표13[[#This Row],[end_use_category]]) -> 0.034040616 | G2: =(표13[[#This Row],[specialty_count]]-MIN(표13[specialty_count]))/(MAX(표13[specialty_count])-MIN(표13[specialty_count]))*10 -> 1.8181818 | H2: =(표13[[#This Row],[specialty_avg_cagr]]-MIN(표13[specialty_avg_cagr]))/(MAX(표13[specialty_avg_cagr])-MIN(표13[specialty_avg_cagr]))*10 -> 5.1469085 | I2: =(표13[[#This Row],[specialty_max_cagr]]-MIN(표13[specialty_max_cagr]))/(MAX(표13[specialty_max_cagr])-MIN(표13[specialty_max_cagr]))*10 -> 0.77720613 | J2: =표13[[#This Row],[norm_count]]*rating!$B$5+표13[[#This Row],[norm_avg]]*rating!$B$6+표13[[#This Row],[norm_max]]*rating!$B$7 -> 3.2223012 | K2: 0 | L2: 0 | M2: =(표13[[#This Row],[stategy_12]]*rating!$B$8+표13[[#This Row],[stategy_50]]*rating!$B$9)*10 -> 0 | O2: =AVERAGE(표13[[#This Row],[specialty_opp]:[ind_growth]]) -> 0.8055753
A3: E02 | B3: Consumer Products & Packaging | C3: Packaging, hygiene, personal care, household products | D3: =COUNTIF(표16[end_use_category],표13[[#This Row],[end_use_category]]) -> 11 | E3: =AVERAGEIF(표16[end_use_category],표13[[#This Row],[end_use_category]],표16[specialty_cagr]) -> 0.027473582 | F3: =_xlfn.MAXIFS(표16[specialty_cagr],표16[end_use_category],표13[[#This Row],[end_use_category]]) -> 0.036406497 | G3: =(표13[[#This Row],[specialty_count]]-MIN(표13[specialty_count]))/(MAX(표13[specialty_count])-MIN(표13[specialty_count]))*10 -> 5.4545455 | H3: =(표13[[#This Row],[specialty_avg_cagr]]-MIN(표13[specialty_avg_cagr]))/(MAX(표13[specialty_avg_cagr])-MIN(표13[specialty_avg_cagr]))*10 -> 5.8637931 | I3: =(표13[[#This Row],[specialty_max_cagr]]-MIN(표13[specialty_max_cagr]))/(MAX(표13[specialty_max_cagr])-MIN(표13[specialty_max_cagr]))*10 -> 1.3701767 | J3: =표13[[#This Row],[norm_count]]*rating!$B$5+표13[[#This Row],[norm_avg]]*rating!$B$6+표13[[#This Row],[norm_max]]*rating!$B$7 -> 4.6380771 | K3: 0.16666667 | L3: 0.06 | M3: =(표13[[#This Row],[stategy_12]]*rating!$B$8+표13[[#This Row],[stategy_50]]*rating!$B$9)*10 -> 1.3466667 | O3: =AVERAGE(표13[[#This Row],[specialty_opp]:[ind_growth]]) -> 1.5528526
A4: E03 | B4: Automotive & Future Mobility | C4: Automotive plastics, elastomers, lightweighting, thermal materials | D4: =COUNTIF(표16[end_use_category],표13[[#This Row],[end_use_category]]) -> 9 | E4: =AVERAGEIF(표16[end_use_category],표13[[#This Row],[end_use_category]],표16[specialty_cagr]) -> 0.01870127 | F4: =_xlfn.MAXIFS(표16[specialty_cagr],표16[end_use_category],표13[[#This Row],[end_use_category]]) -> 0.034040616 | G4: =(표13[[#This Row],[specialty_count]]-MIN(표13[specialty_count]))/(MAX(표13[specialty_count])-MIN(표13[specialty_count]))*10 -> 3.6363636 | H4: =(표13[[#This Row],[specialty_avg_cagr]]-MIN(표13[specialty_avg_cagr]))/(MAX(표13[specialty_avg_cagr])-MIN(표13[specialty_avg_cagr]))*10 -> 2.5273584 | I4: =(표13[[#This Row],[specialty_max_cagr]]-MIN(표13[specialty_max_cagr]))/(MAX(표13[specialty_max_cagr])-MIN(표13[specialty_max_cagr]))*10 -> 0.77720613 | J4: =표13[[#This Row],[norm_count]]*rating!$B$5+표13[[#This Row],[norm_avg]]*rating!$B$6+표13[[#This Row],[norm_max]]*rating!$B$7 -> 2.3670716 | K4: 0.66666667 | L4: 0.42 | M4: =(표13[[#This Row],[stategy_12]]*rating!$B$8+표13[[#This Row],[stategy_50]]*rating!$B$9)*10 -> 5.9266667 | O4: =AVERAGE(표13[[#This Row],[specialty_opp]:[ind_growth]]) -> 2.3451012
A5: E04 | B5: Energy, Power & Utilities | C5: Wire & cable, electrical insulation, solar, refinery, gas treatment | D5: =COUNTIF(표16[end_use_category],표13[[#This Row],[end_use_category]]) -> 9 | E5: =AVERAGEIF(표16[end_use_category],표13[[#This Row],[end_use_category]],표16[specialty_cagr]) -> 0.01205622 | F5: =_xlfn.MAXIFS(표16[specialty_cagr],표16[end_use_category],표13[[#This Row],[end_use_category]]) -> 0.048304526 | G5: =(표13[[#This Row],[specialty_count]]-MIN(표13[specialty_count]))/(MAX(표13[specialty_count])-MIN(표13[specialty_count]))*10 -> 3.6363636 | H5: =(표13[[#This Row],[specialty_avg_cagr]]-MIN(표13[specialty_avg_cagr]))/(MAX(표13[specialty_avg_cagr])-MIN(표13[specialty_avg_cagr]))*10 -> 0 | I5: =(표13[[#This Row],[specialty_max_cagr]]-MIN(표13[specialty_max_cagr]))/(MAX(표13[specialty_max_cagr])-MIN(표13[specialty_max_cagr]))*10 -> 4.3522287 | J5: =표13[[#This Row],[norm_count]]*rating!$B$5+표13[[#This Row],[norm_avg]]*rating!$B$6+표13[[#This Row],[norm_max]]*rating!$B$7 -> 1.9971481 | K5: 0.75 | L5: 0.32 | M5: =(표13[[#This Row],[stategy_12]]*rating!$B$8+표13[[#This Row],[stategy_50]]*rating!$B$9)*10 -> 6.21 | O5: =AVERAGE(표13[[#This Row],[specialty_opp]:[ind_growth]]) -> 2.319287
A6: E05 | B6: Healthcare & Life Sciences | C6: Medical tubing, blood bags, healthcare materials | D6: =COUNTIF(표16[end_use_category],표13[[#This Row],[end_use_category]]) -> 6 | E6: =AVERAGEIF(표16[end_use_category],표13[[#This Row],[end_use_category]],표16[specialty_cagr]) -> 0.030983783 | F6: =_xlfn.MAXIFS(표16[specialty_cagr],표16[end_use_category],표13[[#This Row],[end_use_category]]) -> 0.040228777 | G6: =(표13[[#This Row],[specialty_count]]-MIN(표13[specialty_count]))/(MAX(표13[specialty_count])-MIN(표13[specialty_count]))*10 -> 0.90909091 | H6: =(표13[[#This Row],[specialty_avg_cagr]]-MIN(표13[specialty_avg_cagr]))/(MAX(표13[specialty_avg_cagr])-MIN(표13[specialty_avg_cagr]))*10 -> 7.1988524 | I6: =(표13[[#This Row],[specialty_max_cagr]]-MIN(표13[specialty_max_cagr]))/(MAX(표13[specialty_max_cagr])-MIN(표13[specialty_max_cagr]))*10 -> 2.3281704 | J6: =표13[[#This Row],[norm_count]]*rating!$B$5+표13[[#This Row],[norm_avg]]*rating!$B$6+표13[[#This Row],[norm_max]]*rating!$B$7 -> 4.4087415 | K6: 0.41666667 | L6: 0.28 | M6: =(표13[[#This Row],[stategy_12]]*rating!$B$8+표13[[#This Row],[stategy_50]]*rating!$B$9)*10 -> 3.7566667 | O6: =AVERAGE(표13[[#This Row],[specialty_opp]:[ind_growth]]) -> 2.2155187
A7: E06 | B7: Agriculture | C7: Agricultural film, irrigation, crop protection | D7: =COUNTIF(표16[end_use_category],표13[[#This Row],[end_use_category]]) -> 5 | E7: =AVERAGEIF(표16[end_use_category],표13[[#This Row],[end_use_category]],표16[specialty_cagr]) -> 0.027317235 | F7: =_xlfn.MAXIFS(표16[specialty_cagr],표16[end_use_category],표13[[#This Row],[end_use_category]]) -> 0.030939657 | G7: =(표13[[#This Row],[specialty_count]]-MIN(표13[specialty_count]))/(MAX(표13[specialty_count])-MIN(표13[specialty_count]))*10 -> 0 | H7: =(표13[[#This Row],[specialty_avg_cagr]]-MIN(표13[specialty_avg_cagr]))/(MAX(표13[specialty_avg_cagr])-MIN(표13[specialty_avg_cagr]))*10 -> 5.8043284 | I7: =(표13[[#This Row],[specialty_max_cagr]]-MIN(표13[specialty_max_cagr]))/(MAX(표13[specialty_max_cagr])-MIN(표13[specialty_max_cagr]))*10 -> 0 | J7: =표13[[#This Row],[norm_count]]*rating!$B$5+표13[[#This Row],[norm_avg]]*rating!$B$6+표13[[#This Row],[norm_max]]*rating!$B$7 -> 2.9021642 | K7: 0.16666667 | L7: 0.08 | M7: =(표13[[#This Row],[stategy_12]]*rating!$B$8+표13[[#This Row],[stategy_50]]*rating!$B$9)*10 -> 1.4066667 | O7: =AVERAGE(표13[[#This Row],[specialty_opp]:[ind_growth]]) -> 1.1388744
